<?xml version="1.0"?>
<robot name="leg">

    <material name="green">
        <color rgba = "0.5 0.5 0.5 1" />
    </material>

    <material name="grey">
        <color rgba = "0 0.5 0.1" />
    </material>

    <link name="pelvic_link">
        <visual> 
            <geometry>
                <box size="1.0 0.3 0.2" />
            </geometry>
            <origin xyz = "0.35 -0.15 0" rpy = "0 0 0" />
            <material name="green"/>
        </visual>
    </link>

    <link name="right_base_link">
        <visual>
            <geometry>
                <box size="0.8 0.3 0.2" />
            </geometry>
            <origin xyz = "0.4 0 0" rpy = " 0 0 0" />
            <!-- <origin xyz = "0 0 -0.2" rpy = " 0 1.57 0" /> -->
            <material name="green"/>
        </visual>
    </link>
 
   <!-- <link name="right_second_link">
        <visual> 
            <geometry>
                <box size="0.8 0.3 0.2" />
            </geometry>
            <origin xyz = "0.4 0 0" rpy = "0 0 0" />
            <material name="green"/>
        </visual>
    </link>

    <link name="right_third_link">
        <visual> 
            <geometry>
                <box size="0.4 0.3 0.1" />
            </geometry>
            <origin xyz = "0.1 0 -0.05" rpy = "0 0 0" />
            <material name="green"/>
        </visual>
    </link> -->

    <link name="base_link">
        <visual>
            <geometry>
                <box size="0.8 0.3 0.2" />
            </geometry>
            <origin xyz = "0.4 0 0" rpy = " 0 0 0" />
            <!-- <origin xyz = "0 0 -0.2" rpy = " 0 1.57 0" /> -->
            <material name="green"/>
        </visual>
    </link>

    <link name="second_link">
        <visual> 
            <geometry>
                <box size="0.8 0.3 0.2" />
            </geometry>
            <origin xyz = "0.4 0 0" rpy = "0 0 0" />
            <material name="green"/>
        </visual>
    </link>

    <link name="third_link">
        <visual> 
            <geometry>
                <box size="0.4 0.3 0.1" />
            </geometry>
            <origin xyz = "0.1 0 -0.05" rpy = "0 0 0" />
            <material name="green"/>
        </visual>
    </link>

    <joint name="empty_right_joint" type="revolute">
        <parent link="pelvic_link" />
        <child link="right_base_link" />
        <origin xyz="0.7 0 0" rpy="0 0 1.57" />
        <axis xyz= "0 1 0" />
        <limit lower= "-0.785" upper="0.785" effort="10" velocity="5" />
    </joint>

    <!-- <joint name="empty_right_joint" type="revolute">
        <parent link="pelvic_link" />
        <child link="right_base_link" />
        <origin xyz="0.7 0 0" rpy="0 0 1.57" />
        <axis xyz= "0 1 0" />
        <limit lower= "-0.785" upper="0.785" effort="10" velocity="5" />
    </joint> -->

    <joint name="empty_joint" type="revolute">
        <parent link="pelvic_link" />
        <child link="base_link" />
        <origin xyz="0 0 0" rpy="0 0 1.57" />
        <axis xyz= "0 1 0" />
        <limit lower= "-0.785" upper="0.785" effort="10" velocity="5" />
    </joint>

    <joint name="knee_joint" type="revolute">
        <parent link="base_link" />
        <child link="second_link" />
        <origin xyz="0.8 0 0" rpy="0 0.57 0" />
        <axis xyz= "0 1 0" />
        <limit lower= "-1.57" upper="1.57" effort="10" velocity="5" />
    </joint>

    <joint name="ankle_joint" type="revolute">
        <parent link="second_link" />
        <child link="third_link" />
        <origin xyz="0.8 0 0" rpy="0 -1.57 0" />
        <axis xyz= "0 1 0"/>
        <limit lower= "-1.57" upper="1.57" effort="10" velocity="5" />
    </joint>

</robot>
